<mujoco model="mini_crane_mujoco">
  <option integrator="implicitfast"/>
  <compiler angle="radian" meshdir="mesh/"/>

  <asset>
    <mesh name="base_link" file="base_link.stl" scale="0.001 0.001 0.001"/> <!-- conversion for autocad size -->
    <mesh name="boom_with_mount_2" file="boom_with_mount_2.stl" scale="0.001 0.001 0.001"/>
    <mesh name="winch_pulley_1" file="winch_pulley_1.stl" scale="0.001 0.001 0.001"/>
    <mesh name="luff_1" file="luff_1.stl" scale="0.001 0.001 0.001"/>
  </asset>

  <worldbody>
    <light name="light" pos="0 0 6"/>
    <camera name="fixed" pos="0 -4 1" zaxis="0 -1 0"/>
    <!-- geom name="floor" pos="0 0 0" size="4 4 -.2" type="plane" rgba=".5 .5 .5 1" material="blue_grid"/ -->
    <body name="base" pos="0 0 0.5">  
      <geom type="mesh" contype="0" conaffinity="0" group="1" density="0" rgba="0.8 0 0 1" mesh="base_link"/>
      <!-- geom type="mesh" rgba="0.7 0.7 0.7 1" mesh="base_link"/ -->
      <body name="luff_1" pos="-0.012099 1e-06 0.186">
        <inertial pos="1.5589e-07 -0.000540527 0.0277155" mass="0.357116" diaginertia="0.000108 9.4e-05 5.9e-05"/>
        <joint name="Revolute 1" pos="0 0 0" axis="0 0 1"/>
        <geom pos="0.012099 -1e-06 -0.186" type="mesh" contype="0" conaffinity="0" group="1" density="0" rgba="0.3 0.3 0.3 1" mesh="luff_1"/>
        <!--geom pos="0.012099 -1e-06 -0.186" type="mesh" rgba="0.7 0.7 0.7 1" mesh="luff_1"/ -->
        <body name="boom_with_mount_2" pos="0 -0.019 0.0405">
          <inertial pos="0.173524 0.0273527 0.0402041" quat="-0.0852226 0.698002 -0.10012 0.703922" mass="1.17793" diaginertia="0.1445 0.144446 0.000254894"/>
          <joint name="Revolute 2" pos="0 0 0" axis="0 -1 0" range="-1.22173 1.5708" actuatorfrcrange="-100 100"/>
          <!-- joint name="Revolute 2" pos="0 0 0" axis="0 -1 0"/ -->
          <geom pos="0.012099 0.018999 -0.2265" quat="1 0 0 0" type="mesh" contype="0" conaffinity="0" group="1" density="0" rgba="0.8 0 0 1" mesh="boom_with_mount_2"/>
          <!-- geom pos="0.012099 0.018999 -0.2265" quat="1 0 0 0" type="mesh" rgba="0.7 0.7 0.7 1" mesh="boom_with_mount_2"/ -->
          <body name="winch_pulley_1" pos="-0.16475 0.023982 0.040989">
            <inertial pos="5.6472e-08 -0.00477244 -6.6746e-06" quat="0.707107 0 0 0.707107" mass="0.130263" diaginertia="3.6e-05 2e-05 2e-05"/>
            <joint name="Revolute 3" pos="0 0 0" axis="0 -1 0"/>
            <geom pos="0.176849 -0.004983 -0.267489" quat="1 0 0 0" type="mesh" contype="0" conaffinity="0" group="1" density="0" rgba="0.8 0.5 0 1" mesh="winch_pulley_1"/>
            <!-- geom pos="0.176849 -0.004983 -0.267489" quat="1 0 0 0" type="mesh" rgba="0.7 0.7 0.7 1" mesh="winch_pulley_1"/ -->
          </body> <!-- winch pulley -->

          <body name="boom_front_end" pos="0.74 0.023982 0.040989" >
              <site name="tip" pos="0 -0.004983 0.04" size="0.01" rgba="0.8 0.8 0.8 1"/>
              <site name="tip_lower" pos="0 -0.004983 -0.01" size="0.01" rgba="0.8 0.8 0.8 1"/>
          
              <body name="slider" pos="-0.3 0 0.04">
                <joint name="hoist-slider" type="slide" axis="1 0 0" />
                <geom type="box" size=".005 .005 .005" rgba="0 1 0 1" />
                <site name="hoist_end" pos=".005 0 0" size="0.01"/>
              </body>
          </body>

        </body> <!-- boom -->
      </body> <!-- luff -->
    </body> <!-- base -->

    <body name="payload" pos="1.7 0 .275">
      <joint type="free" name="payload-joint"/>
      <geom name="payload_geom" type="box" size=".01 .01 .05" rgba="0 0 0.7 1" condim="3" contype="1" conaffinity="1" mass="0.02"/>
      <site name="end" pos="0 0 .05" size="0.001" rgba="0 1 0 1"/>
      <site name="p_cg" pos="0 0 0"/>
    </body> <!-- payload -->

    <!-- Table -->
		<!-- body pos="0 0 0.2" name="table0">
			<geom size="0.3 0.3 0.2" type="box" mass="2000" rgba="0.4 0.4 0.4 1"></geom>
		</body -->

  </worldbody>
  
  <tendon>
    <spatial name="rope" limited="true" range="0.1 0.8 " width="0.0005">
      <site site="hoist_end"/>
      <site site="tip"/>
      <site site="tip_lower"/>
      <site site="end"/>
    </spatial>
  </tendon>

    <actuator>
    <intvelocity name="slew-velocity" joint="Revolute 1" actrange="-10000 10000" ctrllimited="true" ctrlrange="-1.57 1.57" kp="500" kv="15"/>
    <intvelocity name="luff-velocity" joint="Revolute 2" actrange="-1.57 1.57" ctrllimited="true" ctrlrange="-.87 .87" kp="500" kv="15"/>
    <position name="hoist-position" joint="hoist-slider"  ctrllimited="true" ctrlrange="-2 2"  kp="100" kv="15"/>
  </actuator>
  
  
</mujoco>
